Traceback (most recent call last):
  File "/home/eric/jb_reports/.venv/lib/python3.12/site-packages/jupyter_cache/executors/utils.py", line 58, in single_nb_execution
    executenb(
  File "/home/eric/jb_reports/.venv/lib/python3.12/site-packages/nbclient/client.py", line 1314, in execute
    return NotebookClient(nb=nb, resources=resources, km=km, **kwargs).execute()
           ^^^^^^^^^^^^^^^^^^^^^^^^^^^^^^^^^^^^^^^^^^^^^^^^^^^^^^^^^^^^^^^^^^^^^
  File "/home/eric/jb_reports/.venv/lib/python3.12/site-packages/jupyter_core/utils/__init__.py", line 165, in wrapped
    return loop.run_until_complete(inner)
           ^^^^^^^^^^^^^^^^^^^^^^^^^^^^^^
  File "/usr/lib/python3.12/asyncio/base_events.py", line 687, in run_until_complete
    return future.result()
           ^^^^^^^^^^^^^^^
  File "/home/eric/jb_reports/.venv/lib/python3.12/site-packages/nbclient/client.py", line 709, in async_execute
    await self.async_execute_cell(
  File "/home/eric/jb_reports/.venv/lib/python3.12/site-packages/nbclient/client.py", line 1062, in async_execute_cell
    await self._check_raise_for_error(cell, cell_index, exec_reply)
  File "/home/eric/jb_reports/.venv/lib/python3.12/site-packages/nbclient/client.py", line 918, in _check_raise_for_error
    raise CellExecutionError.from_cell_and_msg(cell, exec_reply_content)
nbclient.exceptions.CellExecutionError: An error occurred while executing the following cell:
------------------
import nbformat as nbf
from pathlib import Path
def remove_input():
    fn = Path('02_yjbb.ipynb')
    nb = nbf.read(fn, nbf.NO_CONVERT)
    for cell in nb.cells:
        cell_tags = cell.get('metadata', {}).get('tags', [])
        if not 'remove_input' in cell_tags:
            cell_tags.append('remove_input')
            cell['metadata']['tags'] = cell_tags
    nbf.write(nb, fn)
remove_input()
------------------


[0;31m---------------------------------------------------------------------------[0m
[0;31mAttributeError[0m                            Traceback (most recent call last)
File [0;32m~/jb_reports/.venv/lib/python3.12/site-packages/nbformat/__init__.py:169[0m, in [0;36mread[0;34m(fp, as_version, capture_validation_error, **kwargs)[0m
[1;32m    168[0m [38;5;28;01mtry[39;00m:
[0;32m--> 169[0m     buf [38;5;241m=[39m [43mfp[49m[38;5;241;43m.[39;49m[43mread[49m()
[1;32m    170[0m [38;5;28;01mexcept[39;00m [38;5;167;01mAttributeError[39;00m:

[0;31mAttributeError[0m: 'PosixPath' object has no attribute 'read'

During handling of the above exception, another exception occurred:

[0;31mFileNotFoundError[0m                         Traceback (most recent call last)
Cell [0;32mIn[24], line 12[0m
[1;32m     10[0m             cell[[38;5;124m'[39m[38;5;124mmetadata[39m[38;5;124m'[39m][[38;5;124m'[39m[38;5;124mtags[39m[38;5;124m'[39m] [38;5;241m=[39m cell_tags
[1;32m     11[0m     nbf[38;5;241m.[39mwrite(nb, fn)
[0;32m---> 12[0m [43mremove_input[49m[43m([49m[43m)[49m

Cell [0;32mIn[24], line 5[0m, in [0;36mremove_input[0;34m()[0m
[1;32m      3[0m [38;5;28;01mdef[39;00m [38;5;21mremove_input[39m():
[1;32m      4[0m     fn [38;5;241m=[39m Path([38;5;124m'[39m[38;5;124m02_yjbb.ipynb[39m[38;5;124m'[39m)
[0;32m----> 5[0m     nb [38;5;241m=[39m [43mnbf[49m[38;5;241;43m.[39;49m[43mread[49m[43m([49m[43mfn[49m[43m,[49m[43m [49m[43mnbf[49m[38;5;241;43m.[39;49m[43mNO_CONVERT[49m[43m)[49m
[1;32m      6[0m     [38;5;28;01mfor[39;00m cell [38;5;129;01min[39;00m nb[38;5;241m.[39mcells:
[1;32m      7[0m         cell_tags [38;5;241m=[39m cell[38;5;241m.[39mget([38;5;124m'[39m[38;5;124mmetadata[39m[38;5;124m'[39m, {})[38;5;241m.[39mget([38;5;124m'[39m[38;5;124mtags[39m[38;5;124m'[39m, [])

File [0;32m~/jb_reports/.venv/lib/python3.12/site-packages/nbformat/__init__.py:171[0m, in [0;36mread[0;34m(fp, as_version, capture_validation_error, **kwargs)[0m
[1;32m    169[0m     buf [38;5;241m=[39m fp[38;5;241m.[39mread()
[1;32m    170[0m [38;5;28;01mexcept[39;00m [38;5;167;01mAttributeError[39;00m:
[0;32m--> 171[0m     [38;5;28;01mwith[39;00m [38;5;28;43mopen[39;49m[43m([49m[43mfp[49m[43m,[49m[43m [49m[43mencoding[49m[38;5;241;43m=[39;49m[38;5;124;43m"[39;49m[38;5;124;43mutf8[39;49m[38;5;124;43m"[39;49m[43m)[49m [38;5;28;01mas[39;00m f:  [38;5;66;03m# noqa: PTH123[39;00m
[1;32m    172[0m         [38;5;28;01mreturn[39;00m reads(f[38;5;241m.[39mread(), as_version, capture_validation_error, [38;5;241m*[39m[38;5;241m*[39mkwargs)
[1;32m    174[0m [38;5;28;01mreturn[39;00m reads(buf, as_version, capture_validation_error, [38;5;241m*[39m[38;5;241m*[39mkwargs)

[0;31mFileNotFoundError[0m: [Errno 2] No such file or directory: '02_yjbb.ipynb'

