Traceback (most recent call last):
  File "/home/eric/jb_reports/.venv/lib/python3.12/site-packages/jupyter_cache/executors/utils.py", line 58, in single_nb_execution
    executenb(
  File "/home/eric/jb_reports/.venv/lib/python3.12/site-packages/nbclient/client.py", line 1314, in execute
    return NotebookClient(nb=nb, resources=resources, km=km, **kwargs).execute()
           ^^^^^^^^^^^^^^^^^^^^^^^^^^^^^^^^^^^^^^^^^^^^^^^^^^^^^^^^^^^^^^^^^^^^^
  File "/home/eric/jb_reports/.venv/lib/python3.12/site-packages/jupyter_core/utils/__init__.py", line 165, in wrapped
    return loop.run_until_complete(inner)
           ^^^^^^^^^^^^^^^^^^^^^^^^^^^^^^
  File "/usr/lib/python3.12/asyncio/base_events.py", line 687, in run_until_complete
    return future.result()
           ^^^^^^^^^^^^^^^
  File "/home/eric/jb_reports/.venv/lib/python3.12/site-packages/nbclient/client.py", line 709, in async_execute
    await self.async_execute_cell(
  File "/home/eric/jb_reports/.venv/lib/python3.12/site-packages/nbclient/client.py", line 1062, in async_execute_cell
    await self._check_raise_for_error(cell, cell_index, exec_reply)
  File "/home/eric/jb_reports/.venv/lib/python3.12/site-packages/nbclient/client.py", line 918, in _check_raise_for_error
    raise CellExecutionError.from_cell_and_msg(cell, exec_reply_content)
nbclient.exceptions.CellExecutionError: An error occurred while executing the following cell:
------------------
plot_labs(de_banks(list_all_in(sharpe.head(300), [top300[2]])[['cname', 'sharpe_r5', 'count']]))
------------------


[0;31m---------------------------------------------------------------------------[0m
[0;31mNameError[0m                                 Traceback (most recent call last)
Cell [0;32mIn[25], line 1[0m
[0;32m----> 1[0m plot_labs(de_banks([43mlist_all_in[49m(sharpe[38;5;241m.[39mhead([38;5;241m300[39m), [top300[[38;5;241m2[39m]])[[[38;5;124m'[39m[38;5;124mcname[39m[38;5;124m'[39m, [38;5;124m'[39m[38;5;124msharpe_r5[39m[38;5;124m'[39m, [38;5;124m'[39m[38;5;124mcount[39m[38;5;124m'[39m]]))

[0;31mNameError[0m: name 'list_all_in' is not defined

